<?xml version="1.0"?>
<!-- bodhini@jain-->
<!-- URDF DESCRIPTION OF THE DIFFERENTIAL DRIVE     -->
<robot name="differential_drive_robot" xmlns:xacro="http://www.ros.org/wiki/xacro">
<!-- Body dimensions -->
<xacro:property name="body_link_x_dim" value="1"/>
<xacro:property name="body_link_y_dim" value="0.6"/>
<xacro:property name="body_link_z_dim" value="0.3"/>
<!-- Wheel  -->
<xacro:property name="wheel_link_radius" value="0.15"/>
<xacro:property name="wheel_link_length" value="0.1"/>
<xacro:property name="wheel_link_z_location" value="-0.1"/>
<!-- Caster Sphere -->
<xacro:property name="caster_link_radius" value="0.15"/>
<xacro:property name="caster_link_z_location" value="-0.1"/>
<!-- Material Density -->
<xacro:property name="body_density" value="2710.0"/>
<xacro:property name="wheel_density" value="2710.0"/>
<xacro:property name="caster_density" value="2710.0"/>
<!-- Pi Constant -->
<xacro:property name="pi_constant" value="3.1459265"/>
<!-- Robot Mass -->
<xacro:property name="body_mass" value="${body_density*body_link_x_dim*body_link_y_dim*body_link_z_dim}"/>
<xacro:property name="wheel_mass" value="${wheel_density*wheel_link_radius*wheel_link_radius*pi_constant*wheel_link_length}"/>
<xacro:property name="caster_mass" value="${caster_density*(4.0/3.0)*pi_constant*caster_link_radius*caster_link_radius*caster_link_radius}"/>
<!-- Moments of Inertia of wheel -->
<xacro:property name="Iz_wheel" value="${wheel_mass*wheel_link_radius*wheel_link_radius}" />
<xacro:property name="I_wheel" value="${(1.0/12.0)*wheel_mass*(3.0*wheel_link_radius*wheel_link_radius+wheel_link_length)}" />
<!-- Moments of Inertia of caster sphere -->
<xacro:property name="I_caster" value="${(2.0/5.0)*caster_mass*caster_link_radius*caster_link_radius}" />

<!-- Complete Inertial Section of wheel -->
<xacro:macro name="inertia_wheel">
    <inertial>    <origin rpy="0 0 0" xyz="0 0 0"/>
    <mass value="${wheel_mass}"/>
    <inertia ixx="${I_wheel}" ixy="0.0" ixz="0.0" iyy="${I_wheel}" iyz="0" izz="${Iz_wheel}"/>
    </inertial>
</xacro:macro>
<!-- Complete Inertial Section of caster sphere -->
<xacro:macro name="inertia_caster">
    <inertial>
    <origin rpy="0 0 0" xyz="0 0 0"/>
    <mass value="${caster_mass}"/>
    <inertia ixx="${I_caster}" ixy="0.0" ixz="0.0" iyy="${I_caster}" iyz="0" izz="${I_caster}"/>
    </inertial>
</xacro:macro>

<!-- Gazebo points and motion control driver -->
<xacro:include filename="$(find mobile_dd_robot)/model/robot.gazebo" />

<!-- LINKS AND JOINTS -->
<link name="dummy">
</link>
<joint name="dummy_joint" type="fixed">
    <parent link="dummy"/>
    <child link="body_link" />
    
</joint>

<!-- BODY LINK -->
<link name="body_link">
    <visual>
        <geometry>
            <box size="${body_link_x_dim} ${body_link_y_dim} ${body_link_z_dim}" />
        </geometry>
    <origin rpy="0 0 0" xyz="0 0 0"/>
    </visual>
    
    <collision>
        <geometry>
            <box size="${body_link_x_dim} ${body_link_y_dim} ${body_link_z_dim}" />
        </geometry>
    <origin rpy="0 0 0" xyz="0 0 0"/>
    </collision>
    
    <inertial>
         <origin rpy="0 0 0" xyz="0 0 0"/>
         <mass value="${body_mass}"/>
    <inertia 
    ixx="${(1/12)*body_mass*(body_link_y_dim*body_link_y_dim+body_link_z_dim*body_link_z_dim)}" ixy="0"     ixz="0" iyy="${(1/12)*body_mass*(body_link_x_dim*body_link_x_dim+body_link_z_dim*body_link_z_dim)}" iyz="0"
    izz="${(1/12)*body_mass*(body_link_y_dim*body_link_y_dim+body_link_x_dim*body_link_x_dim)}" />
    </inertial>
</link>

<!-- RIGHT WHEEL AND JOINT -->
<joint name="wheel1_joint" type="continuous">
    <parent link= "body_link"/>
    <child link="wheel1_link" />
    <origin xyz="${-2*wheel_link_radius} ${-body_link_y_dim/2-wheel_link_length/2} ${wheel_link_z_location}" rpy="0 0 0"/>
    <axis xyz="0 1 0"/>
    <limit effort="1000" velocity="1000"/>
    <dynamics damping="1.0" friction="1.0"/>
</joint>   
<link name="wheel1_link">
    <visual>
        <origin rpy="1.570795 0 0" xyz="0 0 0"/>
        <geometry>
            <cylinder length="${wheel_link_length}" radius="${wheel_link_radius}" />
        </geometry>
    </visual>
    
    <collision>
        <origin rpy="1.570795 0 0" xyz="0 0 0"/>
        <geometry>
            <cylinder length="${wheel_link_length}" radius="${wheel_link_radius}" />
        </geometry>
    </collision>
    <xacro:inertia_wheel />
</link>

<!-- BACK LEFT WHEEL -->
<joint name="wheel2_joint" type="continuous">
    <parent link= "body_link"/>
    <child link="wheel2_link" />
    <origin xyz="${-2*wheel_link_radius} ${body_link_y_dim/2+wheel_link_length/2} ${wheel_link_z_location}" rpy="0 0 0"/>
    <axis xyz="0 1 0"/>
    <limit effort="1000" velocity="1000"/>
    <dynamics damping="1.0" friction="1.0"/>
</joint>   
<link name="wheel2_link">
    <visual>
        <origin rpy="1.570795 0 0" xyz="0 0 0"/>
        <geometry>
            <cylinder length="${wheel_link_length}" radius="${wheel_link_radius}" />
        </geometry>
    </visual>
    
    <collision>
        <origin rpy="1.570795 0 0" xyz="0 0 0"/>
        <geometry>
            <cylinder length="${wheel_link_length}" radius="${wheel_link_radius}" />
        </geometry>
    </collision>
    <xacro:inertia_wheel />
</link>

<!-- CASTER SPHERE -->
<joint name="caster_joint" type="fixed">
    <parent link= "body_link"/>
    <child link="caster_link" />
    <origin xyz="${2*caster_link_radius} 0 ${caster_link_z_location}" rpy="0 0 0"/>
</joint>   

<link name="caster_link">
    <visual>
        <origin rpy="0 0 0" xyz="0 0 0"/>
        <geometry>
            <sphere radius="${caster_link_radius}" />
        </geometry>
    </visual>
    
    <collision>
        <origin rpy="0 0 0" xyz="0 0 0"/>
        <geometry>
            <sphere radius="${caster_link_radius}" />
        </geometry>
    </collision>
    <xacro:inertia_caster />
</link>
<!-- LIDAR-->
<link name="lidar_link">
    <visual>
        <origin rpy="0 0 0" xyz="0 0 0"/>
        <geometry>
            <cylinder length="0.04" radius="0.04" />
        </geometry>
        <material name="lidar_material">
            <color rgba="0.0 0.0 0.0 1.0"/>
        </material>
    </visual>
    
    <collision>
        <origin rpy="0 0 0" xyz="0 0 0"/>
        <geometry>
            <cylinder length="0.04" radius="0.04" />
        </geometry>
    </collision>
    
    <inertial>
        <origin rpy="0 0 0" xyz="0 0 0"/>
        <mass value="0.1"/>
        <inertia ixx="0.000001" ixy="0" ixz="0" iyy="0.000001" iyz="0" izz="0.000001" />
    </inertial>
</link>

<!-- LIDAR JOINT (mounted on top of body) -->
<joint name="lidar_joint" type="fixed">
    <parent link="body_link"/>
    <child link="lidar_link" />
    <origin xyz="0 0 ${body_link_z_dim/2 + 0.05}" rpy="0 0 0"/>
</joint>
<!-- CAMERA MAST -->

<link name="camera_mast_link">

    <visual>
        <origin xyz="0 0 0.3" rpy="0 0 0"/>
        
        <geometry>
            <cylinder radius="0.02" length="0.8"/>
        </geometry>

        <material name="mast_material">
            <color rgba="0.7 0.7 0.7 1.0"/>
        </material>
    </visual>

    <collision>
        <origin xyz="0 0 0.3" rpy="0 0 0"/>

        <geometry>
            <cylinder radius="0.02" length="0.8"/>
        </geometry>
    </collision>

    <inertial>
        <origin xyz="0 0 0.3" rpy="0 0 0"/>

        <mass value="0.2"/>

        <inertia
            ixx="0.001"
            ixy="0"
            ixz="0"
            iyy="0.001"
            iyz="0"
            izz="0.001"/>
    </inertial>

</link>
<!-- CAMERA MAST JOINT -->

<joint name="camera_mast_joint" type="fixed">

    <parent link="body_link"/>

    <child link="camera_mast_link"/>

    <origin xyz="0 0 ${body_link_z_dim/2}" rpy="0 0 -1.5708"/>

</joint>
<link name="camera_link">
    <visual>
        <origin rpy="0 0 0" xyz="0 0 0"/>
        <geometry>
            <box size="0.05 0.05 0.05"/>
        </geometry>
        <material name="camera_material">
            <color rgba="0.0 0.0 0.0 1.0"/>
        </material>
    </visual>
    
    <collision>
        <origin rpy="0 0 0" xyz="0 0 0"/>
        <geometry>
            <box size="0.05 0.05 0.05"/>
        </geometry>
    </collision>
    
    <inertial>
        <origin rpy="0 0 0" xyz="0 0 0"/>
        <mass value="0.1"/>
        <inertia ixx="0.000001" ixy="0" ixz="0" iyy="0.000001" iyz="0" izz="0.000001"/>
    </inertial>
</link>

<!-- CAMERA JOINT -->
<joint name="camera_joint" type="fixed">
    <parent link="camera_mast_link"/>
    <child link="camera_link"/>
    <origin xyz="0.05 0 0.7" rpy="0.0 0.3 0"/>
</joint>

<!-- END -->

</robot>
